2022-01-21 14:08:54,744 INFO    MainThread:4044 [wandb_setup.py:_flush():71] setting env: {}
2022-01-21 14:08:54,744 INFO    MainThread:4044 [wandb_setup.py:_flush():71] setting login settings: {}
2022-01-21 14:08:54,744 INFO    MainThread:4044 [wandb_init.py:_log_setup():371] Logging user logs to C:\Users\rb01243\OneDrive - University of Surrey\Documents\GitHub\dental_disease\notebooks\wandb\run-20220121_140854-2t6tq898\logs\debug.log
2022-01-21 14:08:54,744 INFO    MainThread:4044 [wandb_init.py:_log_setup():372] Logging internal logs to C:\Users\rb01243\OneDrive - University of Surrey\Documents\GitHub\dental_disease\notebooks\wandb\run-20220121_140854-2t6tq898\logs\debug-internal.log
2022-01-21 14:08:54,745 INFO    MainThread:4044 [wandb_init.py:_jupyter_setup():321] configuring jupyter hooks <wandb.sdk.wandb_init._WandbInit object at 0x0000020A5F82AF70>
2022-01-21 14:08:54,745 INFO    MainThread:4044 [wandb_init.py:init():404] calling init triggers
2022-01-21 14:08:54,745 INFO    MainThread:4044 [wandb_init.py:init():409] wandb.init called with sweep_config: {}
config: {'bcc_epoch': -1, 'qtfilter_epoch': -1, 'qt_thres_mode': '', 'qt_thres': 0.0, 'hybrid_entropy_thres': 0.0, 'hybrid_conf_thres': 0.0, 'weights': 'yolov5s.pt', 'cfg': '', 'data': '../data/iid-tvt.yaml', 'hyp': {'lr0': 0.01, 'lrf': 0.2, 'momentum': 0.937, 'weight_decay': 0.0005, 'warmup_epochs': 3.0, 'warmup_momentum': 0.8, 'warmup_bias_lr': 0.1, 'box': 0.05, 'obj': 1.0, 'cls': 0.5, 'cls_pw': 1.0, 'obj_pw': 1.0, 'iou_t': 0.2, 'anchor_t': 4.0, 'fl_gamma': 0, 'hsv_h': 0.015, 'hsv_s': 0.7, 'hsv_v': 0.4, 'degrees': 0.0, 'translate': 0.1, 'scale': 0.5, 'shear': 0.0, 'perspective': 0.0, 'flipud': 0.0, 'fliplr': 0.5, 'mosaic': 1.0, 'mixup': 0.0, 'copy_paste': 0.0}, 'epochs': 2, 'batch_size': 18, 'imgsz': 640, 'rect': False, 'resume': False, 'nosave': False, 'noval': False, 'noautoanchor': False, 'evolve': None, 'bucket': '', 'cache': None, 'image_weights': False, 'device': '', 'multi_scale': False, 'single_cls': False, 'adam': False, 'sync_bn': False, 'workers': 8, 'project': 'runs/train', 'entity': None, 'name': 'test11', 'exist_ok': False, 'quad': False, 'linear_lr': False, 'label_smoothing': 0.0, 'upload_dataset': False, 'bbox_interval': -1, 'save_period': -1, 'artifact_alias': 'latest', 'local_rank': -1, 'freeze': 0, 'patience': 1100, 'save_dir': 'runs\\train\\test112'}
2022-01-21 14:08:54,745 INFO    MainThread:4044 [wandb_init.py:init():460] starting backend
2022-01-21 14:08:54,745 INFO    MainThread:4044 [backend.py:_multiprocessing_setup():99] multiprocessing start_methods=spawn, using: spawn
2022-01-21 14:08:54,750 INFO    MainThread:4044 [backend.py:ensure_launched():216] starting backend process...
2022-01-21 14:08:54,818 INFO    MainThread:4044 [backend.py:ensure_launched():221] started backend process with pid: 18196
2022-01-21 14:08:54,819 INFO    MainThread:4044 [wandb_init.py:init():469] backend started and connected
2022-01-21 14:08:54,829 INFO    MainThread:4044 [wandb_run.py:_label_probe_notebook():911] probe notebook
2022-01-21 14:08:54,831 INFO    MainThread:4044 [wandb_run.py:_label_probe_notebook():921] Unable to probe notebook: 'NoneType' object has no attribute 'get'
2022-01-21 14:08:54,831 INFO    MainThread:4044 [wandb_init.py:init():533] updated telemetry
2022-01-21 14:08:54,831 INFO    MainThread:4044 [wandb_init.py:init():563] communicating current version
2022-01-21 14:08:59,772 INFO    MainThread:4044 [wandb_init.py:init():568] got version response 
2022-01-21 14:08:59,772 INFO    MainThread:4044 [wandb_init.py:init():578] communicating run to backend with 30 second timeout
2022-01-21 14:09:00,454 INFO    MainThread:4044 [wandb_init.py:init():606] starting run threads in backend
2022-01-21 14:09:05,467 INFO    MainThread:4044 [wandb_run.py:_console_start():1810] atexit reg
2022-01-21 14:09:05,468 INFO    MainThread:4044 [wandb_run.py:_redirect():1684] redirect: SettingsConsole.WRAP
2022-01-21 14:09:05,468 INFO    MainThread:4044 [wandb_run.py:_redirect():1721] Wrapping output streams.
2022-01-21 14:09:05,470 INFO    MainThread:4044 [wandb_run.py:_redirect():1745] Redirects installed.
2022-01-21 14:09:05,470 INFO    MainThread:4044 [wandb_init.py:init():633] run started, returning control to user process
2022-01-21 14:09:05,472 INFO    MainThread:4044 [wandb_run.py:_config_callback():956] config_cb None None {'data_dict': {'path': '../data/datasets/iid-tvt', 'train': '..\\data\\datasets\\iid-tvt\\images\\train', 'val': '..\\data\\datasets\\iid-tvt\\images\\val', 'test': '..\\data\\datasets\\iid-tvt\\images\\test', 'nc': 2, 'names': ['bone-loss', 'dental-caries']}}
2022-01-21 14:10:13,494 INFO    MainThread:4044 [wandb_init.py:_pause_backend():284] pausing backend
2022-01-21 14:10:13,494 INFO    MainThread:4044 [jupyter.py:save_ipynb():374] not saving jupyter notebook
2022-01-21 15:14:14,781 INFO    MainThread:4044 [wandb_init.py:_resume_backend():293] resuming backend
2022-01-21 15:14:16,744 INFO    MainThread:4044 [wandb_init.py:_pause_backend():284] pausing backend
2022-01-21 15:14:16,744 INFO    MainThread:4044 [jupyter.py:save_ipynb():374] not saving jupyter notebook
2022-01-21 15:14:30,473 INFO    MainThread:4044 [wandb_init.py:_resume_backend():293] resuming backend
2022-01-21 15:14:30,545 INFO    MainThread:4044 [wandb_run.py:_config_callback():956] config_cb None None {'data_dict': {'path': '../data/datasets/iid-tvt', 'train': '..\\data\\datasets\\iid-tvt\\images\\train', 'val': '..\\data\\datasets\\iid-tvt\\images\\val', 'test': '..\\data\\datasets\\iid-tvt\\images\\test', 'nc': 2, 'names': ['bone-loss', 'dental-caries']}}
2022-01-21 15:14:34,286 INFO    MainThread:4044 [wandb_init.py:_pause_backend():284] pausing backend
2022-01-21 15:14:34,287 INFO    MainThread:4044 [jupyter.py:save_ipynb():374] not saving jupyter notebook
2022-01-21 15:14:35,448 INFO    MainThread:4044 [wandb_run.py:_atexit_cleanup():1780] got exitcode: 0
2022-01-21 15:14:35,449 INFO    MainThread:4044 [wandb_run.py:_restore():1752] restore
2022-01-21 15:14:37,478 ERROR   MainThread:4044 [wandb_run.py:_atexit_cleanup():1798] Problem finishing run
Traceback (most recent call last):
  File "C:\Users\rb01243\Anaconda3\lib\site-packages\wandb\sdk\wandb_run.py", line 1788, in _atexit_cleanup
    self._on_finish()
  File "C:\Users\rb01243\Anaconda3\lib\site-packages\wandb\sdk\wandb_run.py", line 1934, in _on_finish
    self.history._flush()
  File "C:\Users\rb01243\Anaconda3\lib\site-packages\wandb\sdk\wandb_history.py", line 59, in _flush
    self._callback(row=self._data, step=self._step)
  File "C:\Users\rb01243\Anaconda3\lib\site-packages\wandb\sdk\wandb_run.py", line 1017, in _history_callback
    self._backend.interface.publish_history(
  File "C:\Users\rb01243\Anaconda3\lib\site-packages\wandb\sdk\interface\interface.py", line 496, in publish_history
    data = data_types.history_dict_to_json(run, data, step=step)
  File "C:\Users\rb01243\Anaconda3\lib\site-packages\wandb\sdk\data_types.py", line 2597, in history_dict_to_json
    payload[key] = val_to_json(run, key, val, namespace=step)
  File "C:\Users\rb01243\Anaconda3\lib\site-packages\wandb\sdk\data_types.py", line 2638, in val_to_json
    item.bind_to_run(run, key, namespace, id_=i)
  File "C:\Users\rb01243\Anaconda3\lib\site-packages\wandb\sdk\data_types.py", line 2264, in bind_to_run
    super(Image, self).bind_to_run(run, key, step, id_)
  File "C:\Users\rb01243\Anaconda3\lib\site-packages\wandb\sdk\data_types.py", line 498, in bind_to_run
    raise ValueError(
ValueError: Media Bounding Box Debugger/Images is invalid. Please remove invalid filename characters
