WARNING: Dataset not found, nonexistent paths: ['C:\\Users\\rb01243\\OneDrive - University of Surrey\\Documents\\GitHub\\dental_disease\\datasets\\coco128\\images\\train2017']
Downloading https://github.com/ultralytics/yolov5/releases/download/v1.0/coco128.zip ...
Dataset autodownload failure
100%|â–ˆâ–ˆâ–ˆâ–ˆâ–ˆâ–ˆâ–ˆâ–ˆâ–ˆâ–ˆâ–ˆâ–ˆâ–ˆâ–ˆâ–ˆâ–ˆâ–ˆâ–ˆâ–ˆâ–ˆâ–ˆâ–ˆâ–ˆâ–ˆâ–ˆâ–ˆâ–ˆâ–ˆâ–ˆâ–ˆâ–ˆâ–ˆâ–ˆâ–ˆâ–ˆâ–ˆâ–ˆâ–ˆâ–ˆâ–ˆâ–ˆâ–ˆâ–ˆâ–ˆâ–ˆâ–ˆâ–ˆâ–ˆâ–ˆâ–ˆâ–ˆâ–ˆâ–ˆâ–ˆâ–ˆâ–ˆâ–ˆâ–ˆâ–ˆâ–ˆâ–ˆâ–ˆâ–ˆâ–ˆâ–ˆâ–ˆâ–ˆâ–ˆâ–ˆâ–ˆâ–ˆâ–ˆâ–ˆâ–ˆâ–ˆâ–ˆâ–ˆ| 6.66M/6.66M [00:00<00:00, 55.1MB/s]
                 from  n    params  module                                  arguments
  0                -1  1      3520  models.common.Conv                      [3, 32, 6, 2, 2]
  1                -1  1     18560  models.common.Conv                      [32, 64, 3, 2]
  2                -1  1     18816  models.common.C3                        [64, 64, 1]
  3                -1  1     73984  models.common.Conv                      [64, 128, 3, 2]
  4                -1  2    115712  models.common.C3                        [128, 128, 2]
  5                -1  1    295424  models.common.Conv                      [128, 256, 3, 2]
  6                -1  3    625152  models.common.C3                        [256, 256, 3]
  7                -1  1   1180672  models.common.Conv                      [256, 512, 3, 2]
  8                -1  1   1182720  models.common.C3                        [512, 512, 1]
  9                -1  1    656896  models.common.SPPF                      [512, 512, 5]
 10                -1  1    131584  models.common.Conv                      [512, 256, 1, 1]
 11                -1  1         0  torch.nn.modules.upsampling.Upsample    [None, 2, 'nearest']
 12           [-1, 6]  1         0  models.common.Concat                    [1]
 13                -1  1    361984  models.common.C3                        [512, 256, 1, False]
 14                -1  1     33024  models.common.Conv                      [256, 128, 1, 1]
 15                -1  1         0  torch.nn.modules.upsampling.Upsample    [None, 2, 'nearest']
 16           [-1, 4]  1         0  models.common.Concat                    [1]
 17                -1  1     90880  models.common.C3                        [256, 128, 1, False]
 18                -1  1    147712  models.common.Conv                      [128, 128, 3, 2]
 19          [-1, 14]  1         0  models.common.Concat                    [1]
 20                -1  1    296448  models.common.C3                        [256, 256, 1, False]
 21                -1  1    590336  models.common.Conv                      [256, 256, 3, 2]
 22          [-1, 10]  1         0  models.common.Concat                    [1]
 23                -1  1   1182720  models.common.C3                        [512, 512, 1, False]
 24      [17, 20, 23]  1    229245  models.yolo.Detect                      [80, [[10, 13, 16, 30, 33, 23], [30, 61, 62, 45, 59, 119], [116, 90, 156, 198, 373, 326]], [128, 256, 512]]
C:\Users\rb01243\Anaconda3\lib\site-packages\torch\functional.py:445: UserWarning: torch.meshgrid: in an upcoming release, it will be required to pass the indexing argument. (Triggered internally at  ..\aten\src\ATen\native\TensorShape.cpp:2157.)
  return _VF.meshgrid(tensors, **kwargs)  # type: ignore[attr-defined]
Model Summary: 270 layers, 7235389 parameters, 7235389 gradients, 16.5 GFLOPs
Transferred 350/350 items from yolov5s.pt
Scaled weight_decay = 0.0005
[34m[1moptimizer:[39m[22m SGD with parameter groups 57 weight, 60 weight (no decay), 60 bias
Traceback (most recent call last):
  File "C:\Users\rb01243\OneDrive - University of Surrey\Documents\GitHub\dental_disease\src\utils\datasets.py", line 395, in __init__
    raise Exception(f'{prefix}{p} does not exist')
Exception: [34m[1mtrain: [39m[22m..\datasets\coco128\images\train2017 does not exist
During handling of the above exception, another exception occurred:
Traceback (most recent call last):
  File "C:\Users\rb01243\OneDrive - University of Surrey\Documents\GitHub\dental_disease\src\train.py", line 717, in <module>
    main(opt)
  File "C:\Users\rb01243\OneDrive - University of Surrey\Documents\GitHub\dental_disease\src\train.py", line 615, in main
    train(opt.hyp, opt, device)
  File "C:\Users\rb01243\OneDrive - University of Surrey\Documents\GitHub\dental_disease\src\train.py", line 224, in train
    train_loader, dataset = create_dataloader(train_path, imgsz, batch_size // WORLD_SIZE, gs, single_cls,
  File "C:\Users\rb01243\OneDrive - University of Surrey\Documents\GitHub\dental_disease\src\utils\datasets.py", line 98, in create_dataloader
    dataset = LoadImagesAndLabels(path, imgsz, batch_size,
  File "C:\Users\rb01243\OneDrive - University of Surrey\Documents\GitHub\dental_disease\src\utils\datasets.py", line 400, in __init__
    raise Exception(f'{prefix}Error loading data from {path}: {e}\nSee {HELP_URL}')
Exception: [34m[1mtrain: [39m[22mError loading data from ..\datasets\coco128\images\train2017: [34m[1mtrain: [39m[22m..\datasets\coco128\images\train2017 does not exist
See https://github.com/ultralytics/yolov5/wiki/Train-Custom-Data