2022-01-21 16:51:59 ERROR 405 response executing GraphQL.
2022-01-21 16:51:59 ERROR 
2022-01-21 16:52:00 ERROR 405 response executing GraphQL.
2022-01-21 16:52:00 ERROR 
2022-01-21 16:52:03 ERROR 405 response executing GraphQL.
2022-01-21 16:52:03 ERROR 
2022-01-21 16:52:03 ERROR Retry attempt failed:
Traceback (most recent call last):
  File "C:\Users\rb01243\Anaconda3\lib\site-packages\wandb\sdk\lib\retry.py", line 102, in __call__
    result = self._call_fn(*args, **kwargs)
  File "C:\Users\rb01243\Anaconda3\lib\site-packages\wandb\sdk\internal\internal_api.py", line 147, in execute
    six.reraise(*sys.exc_info())
  File "C:\Users\rb01243\Anaconda3\lib\site-packages\six.py", line 719, in reraise
    raise value
  File "C:\Users\rb01243\Anaconda3\lib\site-packages\wandb\sdk\internal\internal_api.py", line 141, in execute
    return self.client.execute(*args, **kwargs)
  File "C:\Users\rb01243\Anaconda3\lib\site-packages\wandb\vendor\gql-0.2.0\gql\client.py", line 52, in execute
    result = self._get_result(document, *args, **kwargs)
  File "C:\Users\rb01243\Anaconda3\lib\site-packages\wandb\vendor\gql-0.2.0\gql\client.py", line 60, in _get_result
    return self.transport.execute(document, *args, **kwargs)
  File "C:\Users\rb01243\Anaconda3\lib\site-packages\wandb\vendor\gql-0.2.0\gql\transport\requests.py", line 39, in execute
    request.raise_for_status()
  File "C:\Users\rb01243\Anaconda3\lib\site-packages\requests\models.py", line 953, in raise_for_status
    raise HTTPError(http_error_msg, response=self)
requests.exceptions.HTTPError: 405 Client Error: Method Not Allowed for url: https://api.wandb.ai/dddetection/cyolo/graphql
2022-01-21 16:56:48 ERROR Traceback (most recent call last):
  File "C:\Users\rb01243\Anaconda3\lib\site-packages\wandb\cli\cli.py", line 86, in wrapper
    return func(*args, **kwargs)
  File "C:\Users\rb01243\Anaconda3\lib\site-packages\wandb\cli\cli.py", line 224, in login
    settings=wandb.Settings(
  File "C:\Users\rb01243\Anaconda3\lib\site-packages\wandb\sdk\wandb_settings.py", line 456, in __init__
    self._update(kwargs, _source=self.Source.SETTINGS)
  File "C:\Users\rb01243\Anaconda3\lib\site-packages\wandb\sdk\wandb_settings.py", line 907, in _update
    self._check_invalid(k, v)
  File "C:\Users\rb01243\Anaconda3\lib\site-packages\wandb\sdk\wandb_settings.py", line 882, in _check_invalid
    raise UsageError("Settings field `{}`: {}".format(k, invalid))
wandb.errors.UsageError: Settings field `base_url`: https://wandb.ai/dddetection/train is not a valid server address, did you mean https://api.wandb.ai?

2022-01-21 16:57:03 ERROR 405 response executing GraphQL.
2022-01-21 16:57:03 ERROR 
2022-01-21 16:57:04 ERROR 405 response executing GraphQL.
2022-01-21 16:57:04 ERROR 
2022-01-21 16:57:07 ERROR 405 response executing GraphQL.
2022-01-21 16:57:07 ERROR 
2022-01-21 16:57:07 ERROR Retry attempt failed:
Traceback (most recent call last):
  File "C:\Users\rb01243\Anaconda3\lib\site-packages\wandb\sdk\lib\retry.py", line 102, in __call__
    result = self._call_fn(*args, **kwargs)
  File "C:\Users\rb01243\Anaconda3\lib\site-packages\wandb\sdk\internal\internal_api.py", line 147, in execute
    six.reraise(*sys.exc_info())
  File "C:\Users\rb01243\Anaconda3\lib\site-packages\six.py", line 719, in reraise
    raise value
  File "C:\Users\rb01243\Anaconda3\lib\site-packages\wandb\sdk\internal\internal_api.py", line 141, in execute
    return self.client.execute(*args, **kwargs)
  File "C:\Users\rb01243\Anaconda3\lib\site-packages\wandb\vendor\gql-0.2.0\gql\client.py", line 52, in execute
    result = self._get_result(document, *args, **kwargs)
  File "C:\Users\rb01243\Anaconda3\lib\site-packages\wandb\vendor\gql-0.2.0\gql\client.py", line 60, in _get_result
    return self.transport.execute(document, *args, **kwargs)
  File "C:\Users\rb01243\Anaconda3\lib\site-packages\wandb\vendor\gql-0.2.0\gql\transport\requests.py", line 39, in execute
    request.raise_for_status()
  File "C:\Users\rb01243\Anaconda3\lib\site-packages\requests\models.py", line 953, in raise_for_status
    raise HTTPError(http_error_msg, response=self)
requests.exceptions.HTTPError: 405 Client Error: Method Not Allowed for url: https://api.wandb.ai/dddetection/train/graphql
2022-01-21 16:58:12 ERROR 405 response executing GraphQL.
2022-01-21 16:58:12 ERROR 
2022-01-21 16:58:13 ERROR 405 response executing GraphQL.
2022-01-21 16:58:13 ERROR 
2022-01-21 16:58:15 ERROR 405 response executing GraphQL.
2022-01-21 16:58:15 ERROR 
2022-01-21 16:58:15 ERROR Retry attempt failed:
Traceback (most recent call last):
  File "C:\Users\rb01243\Anaconda3\lib\site-packages\wandb\sdk\lib\retry.py", line 102, in __call__
    result = self._call_fn(*args, **kwargs)
  File "C:\Users\rb01243\Anaconda3\lib\site-packages\wandb\sdk\internal\internal_api.py", line 147, in execute
    six.reraise(*sys.exc_info())
  File "C:\Users\rb01243\Anaconda3\lib\site-packages\six.py", line 719, in reraise
    raise value
  File "C:\Users\rb01243\Anaconda3\lib\site-packages\wandb\sdk\internal\internal_api.py", line 141, in execute
    return self.client.execute(*args, **kwargs)
  File "C:\Users\rb01243\Anaconda3\lib\site-packages\wandb\vendor\gql-0.2.0\gql\client.py", line 52, in execute
    result = self._get_result(document, *args, **kwargs)
  File "C:\Users\rb01243\Anaconda3\lib\site-packages\wandb\vendor\gql-0.2.0\gql\client.py", line 60, in _get_result
    return self.transport.execute(document, *args, **kwargs)
  File "C:\Users\rb01243\Anaconda3\lib\site-packages\wandb\vendor\gql-0.2.0\gql\transport\requests.py", line 39, in execute
    request.raise_for_status()
  File "C:\Users\rb01243\Anaconda3\lib\site-packages\requests\models.py", line 953, in raise_for_status
    raise HTTPError(http_error_msg, response=self)
requests.exceptions.HTTPError: 405 Client Error: Method Not Allowed for url: https://api.wandb.ai/dddetection/train/graphql
2022-01-21 17:01:41 ERROR 404 response executing GraphQL.
2022-01-21 17:01:41 ERROR 404 page not found

2022-01-21 17:02:05 ERROR 404 response executing GraphQL.
2022-01-21 17:02:05 ERROR 404 page not found

