2022-01-21 17:03:08,637 INFO    MainThread:3516 [internal.py:wandb_internal():87] W&B internal server running at pid: 3516, started at: 2022-01-21 17:03:08.637525
2022-01-21 17:03:08,638 INFO    WriterThread:3516 [datastore.py:open_for_write():77] open: C:\Users\rb01243\OneDrive - University of Surrey\Documents\GitHub\dental_disease\notebooks\wandb\run-20220121_170307-2xuomf0a\run-2xuomf0a.wandb
2022-01-21 17:03:08,639 DEBUG   HandlerThread:3516 [handler.py:handle_request():130] handle_request: check_version
2022-01-21 17:03:08,640 DEBUG   SenderThread:3516 [sender.py:send():234] send: header
2022-01-21 17:03:08,640 DEBUG   SenderThread:3516 [sender.py:send_request():248] send_request: check_version
2022-01-21 17:03:08,689 DEBUG   SenderThread:3516 [sender.py:send():234] send: run
2022-01-21 17:03:08,697 INFO    SenderThread:3516 [sender.py:_maybe_setup_resume():484] checking resume status for None/YOLOv5/2xuomf0a
2022-01-21 17:03:08,854 ERROR   SenderThread:3516 [internal_api.py:execute():144] 404 response executing GraphQL.
2022-01-21 17:03:08,854 ERROR   SenderThread:3516 [internal_api.py:execute():145] 404 page not found

2022-01-21 17:03:09,699 INFO    WriterThread:3516 [datastore.py:close():281] close: C:\Users\rb01243\OneDrive - University of Surrey\Documents\GitHub\dental_disease\notebooks\wandb\run-20220121_170307-2xuomf0a\run-2xuomf0a.wandb
2022-01-21 17:03:09,699 INFO    HandlerThread:3516 [handler.py:finish():731] shutting down handler
2022-01-21 17:03:09,699 ERROR   MainThread:3516 [internal.py:wandb_internal():158] Thread SenderThread:
Traceback (most recent call last):
  File "C:\Users\rb01243\Anaconda3\lib\site-packages\wandb\sdk\lib\retry.py", line 102, in __call__
    result = self._call_fn(*args, **kwargs)
  File "C:\Users\rb01243\Anaconda3\lib\site-packages\wandb\sdk\internal\internal_api.py", line 147, in execute
    six.reraise(*sys.exc_info())
  File "C:\Users\rb01243\Anaconda3\lib\site-packages\six.py", line 719, in reraise
    raise value
  File "C:\Users\rb01243\Anaconda3\lib\site-packages\wandb\sdk\internal\internal_api.py", line 141, in execute
    return self.client.execute(*args, **kwargs)
  File "C:\Users\rb01243\Anaconda3\lib\site-packages\wandb\vendor\gql-0.2.0\gql\client.py", line 52, in execute
    result = self._get_result(document, *args, **kwargs)
  File "C:\Users\rb01243\Anaconda3\lib\site-packages\wandb\vendor\gql-0.2.0\gql\client.py", line 60, in _get_result
    return self.transport.execute(document, *args, **kwargs)
  File "C:\Users\rb01243\Anaconda3\lib\site-packages\wandb\vendor\gql-0.2.0\gql\transport\requests.py", line 39, in execute
    request.raise_for_status()
  File "C:\Users\rb01243\Anaconda3\lib\site-packages\requests\models.py", line 953, in raise_for_status
    raise HTTPError(http_error_msg, response=self)
requests.exceptions.HTTPError: 404 Client Error: Not Found for url: https://api.wandb.ai/dddetection/graphql

During handling of the above exception, another exception occurred:

Traceback (most recent call last):
  File "C:\Users\rb01243\Anaconda3\lib\site-packages\wandb\apis\normalize.py", line 24, in wrapper
    return func(*args, **kwargs)
  File "C:\Users\rb01243\Anaconda3\lib\site-packages\wandb\sdk\internal\internal_api.py", line 784, in run_resume_status
    response = self.gql(
  File "C:\Users\rb01243\Anaconda3\lib\site-packages\wandb\sdk\lib\retry.py", line 118, in __call__
    if not check_retry_fn(e):
  File "C:\Users\rb01243\Anaconda3\lib\site-packages\wandb\util.py", line 821, in no_retry_auth
    raise CommError("Permission denied, ask the project owner to grant you access")
wandb.errors.CommError: Permission denied, ask the project owner to grant you access

During handling of the above exception, another exception occurred:

Traceback (most recent call last):
  File "C:\Users\rb01243\Anaconda3\lib\site-packages\wandb\sdk\internal\internal_util.py", line 52, in run
    self._run()
  File "C:\Users\rb01243\Anaconda3\lib\site-packages\wandb\sdk\internal\internal_util.py", line 102, in _run
    self._process(record)
  File "C:\Users\rb01243\Anaconda3\lib\site-packages\wandb\sdk\internal\internal.py", line 291, in _process
    self._sm.send(record)
  File "C:\Users\rb01243\Anaconda3\lib\site-packages\wandb\sdk\internal\sender.py", line 236, in send
    send_handler(record)
  File "C:\Users\rb01243\Anaconda3\lib\site-packages\wandb\sdk\internal\sender.py", line 657, in send_run
    error = self._maybe_setup_resume(run)
  File "C:\Users\rb01243\Anaconda3\lib\site-packages\wandb\sdk\internal\sender.py", line 487, in _maybe_setup_resume
    resume_status = self._api.run_resume_status(
  File "C:\Users\rb01243\Anaconda3\lib\site-packages\wandb\apis\normalize.py", line 62, in wrapper
    six.reraise(CommError, CommError(message, err), sys.exc_info()[2])
  File "C:\Users\rb01243\Anaconda3\lib\site-packages\six.py", line 718, in reraise
    raise value.with_traceback(tb)
  File "C:\Users\rb01243\Anaconda3\lib\site-packages\wandb\apis\normalize.py", line 24, in wrapper
    return func(*args, **kwargs)
  File "C:\Users\rb01243\Anaconda3\lib\site-packages\wandb\sdk\internal\internal_api.py", line 784, in run_resume_status
    response = self.gql(
  File "C:\Users\rb01243\Anaconda3\lib\site-packages\wandb\sdk\lib\retry.py", line 118, in __call__
    if not check_retry_fn(e):
  File "C:\Users\rb01243\Anaconda3\lib\site-packages\wandb\util.py", line 821, in no_retry_auth
    raise CommError("Permission denied, ask the project owner to grant you access")
wandb.errors.CommError: Permission denied, ask the project owner to grant you access
2022-01-21 17:03:11,730 INFO    MainThread:3516 [internal.py:handle_exit():77] Internal process exited
