
WARNING: Dataset not found, nonexistent paths: ['/Users/gs0029/repos/dental_disease/notebooks/datasets/iid-tvt/images/val']
Traceback (most recent call last):
  File "../src/train.py", line 716, in <module>
    main(opt)
  File "../src/train.py", line 614, in main
    train(opt.hyp, opt, device)
  File "../src/train.py", line 101, in train
    loggers = Loggers(save_dir, weights, opt, hyp, LOGGER)  # loggers instance
  File "/Users/gs0029/repos/dental_disease/src/utils/loggers/__init__.py", line 62, in __init__
    self.wandb = WandbLogger(self.opt, run_id)
  File "/Users/gs0029/repos/dental_disease/src/utils/loggers/wandb/wandb_utils.py", line 174, in __init__
    self.data_dict = check_wandb_dataset(opt.data)
  File "/Users/gs0029/repos/dental_disease/src/utils/loggers/wandb/wandb_utils.py", line 51, in check_wandb_dataset
    return check_dataset(data_file)
  File "/Users/gs0029/repos/dental_disease/src/utils/general.py", line 310, in check_dataset
    raise Exception('Dataset not found.')
Exception: Dataset not found.